Workbook

Sheet 취합
B1: 팀 3 · 내수·디펜시브 — 담당 산업 스크리닝 취합
B2: ICOK Fund 26-2 · 기준일 2026-09-15 종가 · 취합 2026-09-22 · 팀장 조찬형
B5: 담당 산업 | C5: 담당자 | D5: BM비중 | E5: 종목수 | F5: Top 1 | G5: Top 2 | H5: Top 3 | I5: 탈락 | J5: 상태
B6: 헬스케어·바이오 | C6: 윤지원 | D6: ='헬스케어·바이오'!B5 -> 3.87% | E6: =VALUE('헬스케어·바이오'!H5) -> 42 | F6: ='헬스케어·바이오'!B55 -> 삼성바이오로직스 | G6: ='헬스케어·바이오'!B56 -> 알테오젠 | H6: ='헬스케어·바이오'!B57 -> 한미약품 | I6: =COUNTA('헬스케어·바이오'!B58:B62) -> 5 | J6: 제출
B7: 금융 — 보험·증권 | C7: 조찬형 | D7: ='금융 — 보험·증권'!B5 -> 3.77% | E7: =VALUE('금융 — 보험·증권'!H5) -> 19 | F7: ='금융 — 보험·증권'!B32 -> DB손해보험 | G7: ='금융 — 보험·증권'!B33 -> 삼성생명 | H7: ='금융 — 보험·증권'!B34 -> 한국금융지주 | I7: =COUNTA('금융 — 보험·증권'!B35:B39) -> 5 | J7: 제출
B8: 금융 — 은행·지주 | C8: 고낭균 | D8: ='금융 — 은행·지주'!B5 -> 4.12% | E8: =VALUE('금융 — 은행·지주'!H5) -> 9 | F8: ='금융 — 은행·지주'!B22 -> 하나금융지주 | G8: ='금융 — 은행·지주'!B23 -> 신한지주 | H8: ='금융 — 은행·지주'!B24 -> JB금융지주 | I8: =COUNTA('금융 — 은행·지주'!B25:B29) -> 5 | J8: 제출
B9: 통신·미디어·엔터 | C9: 이서현 | D9: ='통신·미디어·엔터'!B5 -> 1.11% | E9: =VALUE('통신·미디어·엔터'!H5) -> 13 | F9: ='통신·미디어·엔터'!B25 -> LG유플러스 | G9: ='통신·미디어·엔터'!B26 -> SK텔레콤 | H9: ='통신·미디어·엔터'!B27 -> 에스엠 | I9: =COUNTA('통신·미디어·엔터'!B28:B32) -> 5 | J9: 제출
B10: 소비재·유통 | C10: 서민지 | D10: ='소비재·유통'!B5 -> 2.62% | E10: =VALUE('소비재·유통'!H5) -> 32 | F10: ='소비재·유통'!C44 -> 에이피알 | G10: ='소비재·유통'!C45 -> 삼양식품 | H10: ='소비재·유통'!C46 -> 코스맥스 | I10: =COUNTA('소비재·유통'!C47:C51) -> 5 | J10: 제출
B11: 팀 3 합계 | D11: =TEXT(SUMPRODUCT(VALUE(SUBSTITUTE(D6:D10,"%",""))),"0.00")&"%" -> 15.49% | E11: =SUM(E6:E10) -> 115 | I11: =SUM(I6:I10) -> 25
B13: 발제 후보 15종목 — 매수 가능 여부
B14: 담당 산업 | C14: 담당자 | D14: 종목 | E14: 주가 | F14: 1주 / 팀예산 | G14: 매수 판정
B15: 헬스케어·바이오 | C15: 윤지원 | D15: ='헬스케어·바이오'!B11 -> 삼성바이오로직스 | E15: ='헬스케어·바이오'!D11 -> 1412000 | F15: ='헬스케어·바이오'!G11 -> 0.32834046 | G15: ='헬스케어·바이오'!H11 -> 가능
B16: 헬스케어·바이오 | C16: 윤지원 | D16: ='헬스케어·바이오'!B13 -> 알테오젠 | E16: ='헬스케어·바이오'!D13 -> 260000 | F16: ='헬스케어·바이오'!G13 -> 0.060459292 | G16: ='헬스케어·바이오'!H13 -> 가능
B17: 헬스케어·바이오 | C17: 윤지원 | D17: ='헬스케어·바이오'!B14 -> 한미약품 | E17: ='헬스케어·바이오'!D14 -> 496500 | F17: ='헬스케어·바이오'!G14 -> 0.11545399 | G17: ='헬스케어·바이오'!H14 -> 가능
B18: 금융 — 보험·증권 | C18: 조찬형 | D18: ='금융 — 보험·증권'!B15 -> DB손해보험 | E18: ='금융 — 보험·증권'!D15 -> 188700 | F18: ='금융 — 보험·증권'!G15 -> 0.043879494 | G18: ='금융 — 보험·증권'!H15 -> 가능
B19: 금융 — 보험·증권 | C19: 조찬형 | D19: ='금융 — 보험·증권'!B11 -> 삼성생명 | E19: ='금융 — 보험·증권'!D11 -> 285500 | F19: ='금융 — 보험·증권'!G11 -> 0.066388953 | G19: ='금융 — 보험·증권'!H11 -> 가능
B20: 금융 — 보험·증권 | C20: 조찬형 | D20: ='금융 — 보험·증권'!B16 -> 한국금융지주 | E20: ='금융 — 보험·증권'!D16 -> 191200 | F20: ='금융 — 보험·증권'!G16 -> 0.044460833 | G20: ='금융 — 보험·증권'!H16 -> 가능
B21: 금융 — 은행·지주 | C21: 고낭균 | D21: ='금융 — 은행·지주'!B13 -> 하나금융지주 | E21: ='금융 — 은행·지주'!D13 -> 137600 | F21: ='금융 — 은행·지주'!G13 -> 0.031287784 | G21: ='금융 — 은행·지주'!H13 -> 가능
B22: 금융 — 은행·지주 | C22: 고낭균 | D22: ='금융 — 은행·지주'!B12 -> 신한지주 | E22: ='금융 — 은행·지주'!D12 -> 112200 | F22: ='금융 — 은행·지주'!G12 -> 0.025512278 | G22: ='금융 — 은행·지주'!H12 -> 가능
B23: 금융 — 은행·지주 | C23: 고낭균 | D23: ='금융 — 은행·지주'!B17 -> JB금융지주 | E23: ='금융 — 은행·지주'!D17 -> 32200 | F23: ='금융 — 은행·지주'!G17 -> 0.0073217054 | G23: ='금융 — 은행·지주'!H17 -> 가능
B24: 통신·미디어·엔터 | C24: 이서현 | D24: ='통신·미디어·엔터'!B13 -> LG유플러스 | E24: ='통신·미디어·엔터'!D13 -> 14850 | F24: ='통신·미디어·엔터'!G13 -> 0.003376625 | G24: ='통신·미디어·엔터'!H13 -> 가능
B25: 통신·미디어·엔터 | C25: 이서현 | D25: ='통신·미디어·엔터'!B10 -> SK텔레콤 | E25: ='통신·미디어·엔터'!D10 -> 88000 | F25: ='통신·미디어·엔터'!G10 -> 0.02000963 | G25: ='통신·미디어·엔터'!H10 -> 가능
B26: 통신·미디어·엔터 | C26: 이서현 | D26: ='통신·미디어·엔터'!B16 -> 에스엠 | E26: ='통신·미디어·엔터'!D16 -> 87500 | F26: ='통신·미디어·엔터'!G16 -> 0.019895939 | G26: ='통신·미디어·엔터'!H16 -> 가능
B27: 소비재·유통 | C27: 서민지 | D27: ='소비재·유통'!B12 -> 에이피알 | E27: ='소비재·유통'!D12 -> 361500 | F27: ='소비재·유통'!G12 -> 0.082198649 | G27: ='소비재·유통'!H12 -> 가능
B28: 소비재·유통 | C28: 서민지 | D28: ='소비재·유통'!B13 -> 삼양식품 | E28: ='소비재·유통'!D13 -> 1277000 | F28: ='소비재·유통'!G13 -> 0.29036701 | G28: ='소비재·유통'!H13 -> 가능
B29: 소비재·유통 | C29: 서민지 | D29: ='소비재·유통'!B23 -> 코스맥스 | E29: ='소비재·유통'!D23 -> 273000 | F29: ='소비재·유통'!G23 -> 0.062075328 | G29: ='소비재·유통'!H23 -> 가능
B31: 완료 5/5. 5개 산업 모두 Top 3와 탈락 5종목을 채웠다. 발제 후보 15종목 중 매수 제약(IC 2/3 · 매수 불가)에 걸리는 종목은 0종목이다.
B32: 양식 버전이 섞여 있다. 헬스케어·바이오(윤지원)와 금융 — 보험·증권(조찬형)은 구버전 양식(팀 예산 4,300,414원), 나머지 3개는 신버전(4,397,883원)이다. 두 시트의 「1주 / 팀예산」은 구버전 예산 기준이다.
B33: 헬스케어·바이오는 구버전이라 42종목(BM 3.87%)이다. 신버전은 삼성에피스홀딩스·한미사이언스가 추가된 44종목(4.09%)이다. 두 종목 검토를 추가한다.
B34: 「지주 — 내수·소비」는 신버전에서 폐지돼 넣지 않았다. 소속 8종목은 소비재·유통(6종목)과 헬스케어·바이오(2종목)로 옮겨졌다.
B35: 판정 칸에 드롭다운(Top1~3 / 보류 / 탈락) 대신 자유 입력을 쓴 시트가 있다. 헬스케어·바이오 「매수」, 은행·지주 「매수」·「메수」(오타), 보험·증권 「Top 1」·「탈락 1」. 집계 시 주의한다.
B36: 전 종목 검토가 비어 있다. 헬스케어·바이오 29종목, 소비재·유통 18종목, 보험·증권 7종목은 재무지표(CAGR~PER/PBR)와 판정이 공란이다.
B37: 소비재·유통은 선정 결과 종목명을 B열이 아닌 C열에 적었고 Top 1~3 선정 근거가 없다. 근거 2줄을 채운다.
B38: 은행·지주의 「매출 CAGR(3Y)」 칸에 비율이 아닌 금액(원 단위)이 들어가 있고, ROE가 1.9~3.2%로 연간 수치로 보기 어렵다. 분기 수치인지 확인한다. 탈락 2 종목명 「KB끔융」은 오타다.
B39: 작성요령상 「저평가되어 있다」 같은 검증 불가 표현과 개략값(약 ○배)은 쓰지 않는다. 보험·증권(O11·O13·O16·O22·C38), 은행·지주(O13~O15·O18·O19·C22·C27~C29), 소비재·유통(O15·O22)에 남아 있다.
B40: 헬스케어·바이오, 보험·증권, 통신·미디어·엔터 시트의 상단 담당자·제출일은 비어 있어 취합 시 채웠다. 제출일은 윤지원 9/22 · 조찬형 9/21 · 이서현 9/22다.
B41: 삼성바이오로직스는 1주 1,412,000원이 팀 예산의 32.1%(신버전 기준), 삼양식품은 29.0%다. 편입 시 나머지 후보의 자리를 먼저 계산한다.
B42: 원본 파일은 각자 전체 시트를 반환했다. 이 파일은 팀 3 담당 5시트와 작성요령만 남기고 시트명 앞 「3_」을 지웠다. 개인 참고 시트(분석자료 · 데이터가이드6 · Sheet1)는 제외했다.

Sheet 작성요령
B1: 담당 산업 스크리닝 작성요령
B2: ICOK Fund 26-2 · 기준일 2026-09-15 종가
B5: 과제 개요 | C5: 담당 산업의 전 종목을 검토하여 발제 후보 3종목을 선정한다.
C6: 선정한 3종목 중 1종목을 10월 13일 세션에서 발제한다.
C7: 선정 근거와 함께 탈락 근거를 반드시 기재한다.
B9: 작성 순서 | C9: 1. 하위 테마를 2~4개로 분류한다. 예) 에너지 → 태양광 / 풍력 / 원자력 / ESS
C10: 2. 매출 CAGR(3년) · 영업이익률 · ROE · PER(또는 PBR)을 기입한다.
C11: 3. 주요 제품과 시장 포지셔닝을 각 한 줄로 기입한다.
C12: 4. 판정 칸에 Top1~3 / 보류 / 탈락을 선택한다.
C13: 5. 시트 하단 「선정 결과」에 Top 3 근거와 탈락 5종목 사유를 기입한다.
B15: 기입 완료 항목 | C15: 기업명 · 종목코드 · 주가 · 시가총액 · 지수 비중 · 1주가 팀 예산에서 차지하는 비중 · 매수 판정
C16: 음영 처리된 셀이며 수정하지 않는다.
B18: 지수 비중 | C18: KRX 300 비중은 해당 종목의 중립 비중이다.
C19: 예) 비중 0.5% 종목을 1.5% 편입 → 액티브 +1.0%p / 미편입 → 액티브 −0.5%p
C20: 지수 미편입 종목은 중립 비중이 0이므로 편입 시 전량 액티브 포지션으로 기록된다.
B22: 매수 판정 | C22: 1주 가격이 높아 최소 매수 단위만으로 한도를 초과하는 종목이 있다. 종목 선정 전에 확인한다.
C23: 가능 = 팀 재량 / IC 2/3 = 펀드 IC 특별의결 / 매수 불가 = 1주도 편입 불가
C24: 예) 효성중공업 : 지수 비중 0.47%, 1주 2,689,000원 → 1주 매수 시 한도 초과
B26: 자료 기준 | C26: 모든 수치에 출처와 기준일을 기재한다.
C27: 1순위 자료는 DART 사업보고서이며, 증권사 리포트는 참고 자료로만 사용한다.
B29: 작성 시 유의사항 | C29: 증권사 리포트를 논지의 근거로 사용하지 않는다. 목표주가를 인용하지 않는다.
C30: 검증 불가능한 표현(유망하다, 성장성이 크다, 저평가되어 있다 등)을 사용하지 않는다.
C31: 수치를 개략값(약 ○조 등)으로 기재하지 않는다.

Sheet 헬스케어·바이오
A1: 헬스케어·바이오
A2: ICOK Fund 26-2 · 담당 산업 스크리닝
A4: 팀 | B4: 팀 3 · 내수·디펜시브 | D4: 담당자 | E4: 윤지원 | G4: 제출일 | H4: 46287
A5: 지수 비중 | B5: 3.87% | D5: 배정액 | E5: 1,083,543원 | G5: 종목 수 | H5: 42 | J5: 기준일 | K5: 2026-09-15
A7: 42종목 중 다수가 매출 미발생 임상 단계 기업이다. 매출·영업이익률·PER 산출이 불가능한 기업은 하위 테마에 「파이프라인」으로 표기한다.
A8: 음영 셀은 기입 완료. 흰색 셀만 작성한다.
A10: 하위 테마 | B10: 기업명 | C10: 코드 | D10: 주가 | E10: 시가총액(조) | F10: 지수 비중 | G10: 1주 / 팀예산 | H10: 매수 판정 | I10: 매출 CAGR(3Y) | J10: 영업이익률 | K10: ROE | L10: PER / PBR | M10: 주요 제품 | N10: 시장 포지셔닝 | O10: 투자포인트 / 탈락 사유 | P10: 출처 · 기준일 | Q10: 판정
B11: 삼성바이오로직스 | C11: 207940 | D11: 1412000 | E11: 65.362823 | F11: 0.012272183 | G11: 0.32834046 | H11: 가능 | I11: 0.246 | J11: 0.4527 | K11: 0.1076 | L11: 73.46배/7.90배 | M11: 바이오의약품 위탁생산 및 세포주ㆍ공정 개발의 위탁 개발 서비스를 제공하는CDMO 사업 추가로 mRNA, ADC, 세포/유전자 치료제 등 차세대 바이오의약품으로 사업 영역 확장 중 | N11: 대부분 유럽에서 매출 발생(59.3%), 인적분할 절차를 완료하며 본연의 위탁개발생산(CDMO) 사업에 집중하기 위한 체제로 전환하여 순수 위탁개발생산(CDMO) 기업으로서의 글로벌 경쟁력을 더욱 강화할 계획 | O11: 매출 2.58조 원, 영업이익 1.17조 원으로 영업이익률이 45.3%. 글로벌 대형 제약사들과의 장기 CDMO 계약을 바탕으로 시가총액 66조 원 수준의 바이오 대장주 위치. | P11: 반기보고서 | Q11: 매수
B12: 셀트리온 | C12: 068270 | D12: 177500 | E12: 41.289549 | F12: 0.0077523105 | G12: 0.041275093 | H12: 가능 | I12: 0.384 | J12: 0.3048 | K12: 0.04 | L12: 57.37배/2.29배 | M12: 생명공학 기술을 기반으로 자가면역질환, 종양 등 질병의 치료에 사용되는 의약품을 개발 및 상업화하는 것을 주요 목적 사업으로 하는 글로벌 생명공학 기업(바이오의약품, 케미컬의약품, 기타) | N12: 당사가 설립한 해외현지법인을 통한 직접판매 방식과 해외 제약사와의 판매계약에 따른 간접판매 방식으로 구분됨. 유럽, 아시아, 중남미, 미국, 캐나다 등에서 전 제품을 안정적으로 직접판매 | O12: 영업이익률 30.5%로 양호하지만 통합 셀트리온 출범 이후 ROE 4.0%로 한동안 낮게 유지되고 있기 때문 | P12: 반기보고서 | Q12: 보류
B13: 알테오젠 | C13: 196170 | D13: 260000 | E13: 18.110335 | F13: 0.0034003021 | G13: 0.060459292 | H13: 가능 | I13: 0.497 | J13: 0.523 | K13: 0.1852 | L13: 141.28배/26.16배 | M13: 정맥주사 제형을 피하주사 제형으로 전환해주는 히알루로니다제 단백질 공학 기술, 지속형 바이오의약품 기반 기술인 NexP™ 융합, 차세대 항체-약물접합체 기반 기술인 NexMab™ (ADC 기술) 등 플랫폼 기술 등을 기반으로 바이오의약품(바이오베터, 바이오신약 등)의 연구개발, 생산 및 판매 활동을 영위 | N13: 핵심 자산인 ALT-B4를 사용한 피하주사(SC) 제형으로 기존 정맥주사(IV) 제형에 비해 환자의 투약 편의성 및 약물전달의 효율을 증대시키고 전반적인 의료 비용 절감 가능. 글로벌 제약사의 정맥주사 제품 외에 피하주사 제품을 추가함으로써 특허 연장 수단으로 활용할 수 있으며, 전 세계에서 가장 큰 의약품 시장인 미국의 메디케어 약가 인하 협상에서도 제외될 가능성 | O13: SC 제형 변경 기술(ALT-B4)의 기술이전으로 ROE 18.5%의 높은 수익성을 기록 중. 성장성 관점에서 좋다고 생각함. | P13: 반기보고서 | Q13: 매수
B14: 한미약품 | C14: 128940 | D14: 496500 | E14: 6.360657 | F14: 0.0011942438 | G14: 0.11545399 | H14: 가능 | I14: 0.019 | J14: 0.2148 | K14: 0.0851 | L14: 43.95배/3.74배 | M14: 의약품(이상지질혈증치료제 '로수젯', 복합고혈압치료제 '아모잘탄', 역류성식도염치료제 '에소메졸', 전립선비대증치료제 '한미탐스캡슐', 발기부전치료제 '팔팔정' 등) 원료의약품(PEG, mRNA Capping 개발 등 차세대 의약품 분야에서도 기술 경쟁력을 확보하며 API 사업을 넘어 CDMO를 포함한 고부가가치 사업 구조로의 전환을 본격화), 해외의약품(어린이용 정장제 '마미아이'와 기침가래약 '이탄징'이며, 성인용정장제 '매창안' 등) | N14: 스마트폰 등을 이용한 현장 중심의 영업, 적극적인 학회 참여 및 학술활동 강화, 축적된 임상 데이터를 통한 제품의 특장점 홍보, 철저한 시장분석을 통한 제품 포트폴리오 구성 | O14: 자체 개량신약 중심의 안정적 실적과 비만치료제 파이프라인으로 성장성 좋음 | P14: 반기보고서 | Q14: 매수
B15: SK바이오팜 | C15: 326030 | D15: 78100 | E15: 6.116265 | F15: 0.001148358 | G15: 0.018161041 | H15: 가능 | I15: 0.412 | J15: 0.3931 | K15: 0.1838 | L15: 33.32배/6.12배 | M15: 뇌전증 치료 신약 세노바메이트(98.5%), 수면장애 신약 솔리암페놀(1.5%), 기타 | N15: 거대한 글로벌 신약 시장을 타겟으로 중추신경계 분야 중 특히 뇌전증 분야의 혁신 신약 개발에 집중, 직접 판매하고 있는 미국시장 제외, 유럽을 포함한 중국, 일본, 한국, 호주, 캐나다, 라틴아메리카, 중동 및 북아프리카(MENA) 지역 등 대부분의 국가에 기술수출 계약 체결 | O15: SK바이오팜은 뇌전증 치료제(엑스코프리) 흑자 전환 가속화로 펀더멘털이 급격히 개선되는 중 | P15: 반기보고서 | Q15: 매수
B16: 유한양행 | C16: 000100 | D16: 79300 | E16: 5.837731 | F16: 0.0010960619 | G16: 0.018440084 | H16: 가능 | I16: 0.101 | J16: 0.0649 | K16: 0.037 | L16: 71.09배/2.63배 | M16: 의약품: 렉라자, 로수바미브,코푸시럽,삐콤씨 등, 식음료품: 내일엔 등, 생활용품: 유한락스, 유한젠, 주방/세탁세제, AHC: 웰니스, 델라콘 등, 수출: 에이즈 치료제, C형 간염 치료제, 항생제 등, 부동산 매매업: 임대, 화장품: 단시, 더마푸라민 등 | N16: R&D 부문에서 혁신신약 렉라자가 글로벌 시장에서 올해부터 본격적인 사용량 증가가 예상되며, 제2, 제3의 렉라자 출시를 위한 중점 파이프라인 개발도 차질 없이 진행되고 있음. | O16: 렉라자 FDA 승인 모멘텀은 크지만 기존 제약 사업의 낮은 ROE 때문 | P16: 반기보고서 | Q16: 탈락
B17: HLB | C17: 028300 | D17: 32450 | E17: 4.322282 | F17: 0.00081152914 | G17: 0.0075457847 | H17: 가능 | I17: 0.402 | J17: -0.9701 | K17: -0.2871 | L17: 산출불가/9.37배 | M17: 헬스케어: 체외진단 의료기기, 의약외품, 의료소모품 등, 바이오: 리보세라닙, 리라푸그라티닙 등 항암신약개발, 선박: 특수선, 구명정, DAVIT, PIPE 등, 미디어커머스: 뷰티 디바이스 | N17: 기능성 바이오 소재 등의 신기술개발을 목적으로 첨단 바이오 신약개발연구소를 설립 예정, '릴레이 테라퓨틱스'의 담관암 치료제 'RLY-4008(성분명 리라푸그라티닙)'에 대한 글로벌 독점 라이선스-인 계약을 체결 | O17: 영업이익 적자 | P17: 반기보고서 | Q17: 탈락
B18: 삼천당제약 | C18: 000250 | D18: 157500 | E18: 3.694552 | F18: 0.00069366983 | G18: 0.036624379 | H18: 가능 | I18: 0.096 | J18: 0.0655 | K18: 0.0327 | L18: 269.80배/8.83배 | M18: 의약품: 안과용제(하메론, 티어린프리 등)), 순환기 질환 치료제(아토로우, 지텐션 등), 호흡기 질환 치료제(소담, 타리에스 등), 소화기계용제(산화마그네슘, 모푸렌 등), 항생제(크라목스, 파클 등), 소염제(에스부펜, 록소펜 등) | N18: 독소루비신·GLP-1 등 주사제를 경구용(알약)으로 바꾸는 플랫폼 보유, 유럽/북미 글로벌 유통 계약 체결 | O18: 영업이익률(6.6%)과 ROE(3.3%) 대비 PER이 270배 수준으로 신약 기대감이 주가에 과도하게 선반영되어 있어 이후 하락할 가능성 크기 때문 | P18: 반기보고서 | Q18: 탈락
B19: 펩트론 | C19: 087010 | D19: 150800 | E19: 3.516256 | F19: 0.0006601939 | G19: 0.035066389 | H19: 가능 | I19: 0.302 | J19: -4.023 | K19: -0.1068 | L19: 산출불가/3.05배 | M19: 펩타이드 공학 및 약효지속화 원천기술을 기반 약효지속성 스마트 의약품의 설계, 제조 및 펩타이드 신약 개발 | N19: 독자적 SmartDepot(스마트데포) 기술을 통해 약물의 체내 체류 시간을 최적화하는 플랫폼 기술을 보유, 이를 구현할 수 있는 GMP 대량생산 시설을 구축하여 임상용 의약품 및 상업화 제품 생산 능력 확보 | O19: 영업이익 적자 | P19: 반기보고서 | Q19: 탈락
B20: 파마리서치 | C20: 214450 | D20: 337000 | E20: 3.501311 | F20: 0.00065738791 | G20: 0.078364544 | H20: 가능 | I20: 0.435 | J20: 0.381 | K20: 0.1331 | L20: 33.59배/4.47배 | M20: PDRN/PN 기반 의료기기, 화장품, 의약품, 기타 PDRN: 특정 규격의 뉴클레오티드 분절체, 조직재생효능 가짐 또한 인체 세포에 상시 존재하며 생리적으로 섬유아세포의 재생 및 대사 활성을 자극하여 최상의 컨디션을 유지할 수 있도록 돕는 작용 | N20: 기존의 의약품 수입 및 유통 사업에 그치지 않고 국책기관과 함께 조직재생에 효능을가지고 있는 PDRN/PN 관련 제조 기술을 확보, 리쥬란, 관절강 주사인 콘쥬란 및 기타 제품의 국내 상용화에 성공, 우수한 기술경쟁력을 기반으로 한 의료기기, 화장품, 의약품 제조업체로서 R&D를 통한 제품개발 및 시장 확대에 힘쓰며 해외 사업 또한 진행 중 | O20: 리쥬란 등 에스테틱 제품의 안정적인 현금창출력과 해외에서의 큰 매출 | P20: 반기보고서 | Q20: 보류
B21: 에이비엘바이오 | C21: 298380 | D21: 59300 | E21: 3.320057 | F21: 0.0006233566 | G21: 0.013789369 | H21: 가능 | I21: 0.098 | J21: -1.0364 | K21: -0.1705 | L21: 산출불가/18.92배 | M21: 기술이전수익(국내외 제약사와의 기술이전 또는 공동개발에 대한 계약 체결-> 바이오 의약품 개발 단계에 따라 선수수수료, 단계별 마일스톤 및 제품 출시이후 판매액의 일정 부분에 해당하는 로열티 받게 됨) | N21: 파이프라인 및 시장의 성격, 당사의 우수한 기술력 등에 근거하여 빠른 기술이전이 가능할 것으로 예상하고 있음.조기 기술이전은 전략적인 파이프라인 또는 새로운 기술 개발을 위한 자원의 집중을 가능하게 하면서 경쟁력 있는 파이프라인을 유지 가능 | O21: 영업 이익 적자 | P21: 반기보고서 | Q21: 탈락
B22: 리가켐바이오 | C22: 141080 | D22: 83700 | E22: 3.098525 | F22: 0.00058176291 | G22: 0.019463241 | H22: 가능 | I22: 1.035 | J22: -2.641 | K22: -0.23 | L22: 산출불가/6.92배 | M22: 의약화학 기반 글로벌 신약 R&D 주력 연구중심형 제약회사 ADC(항체-약물 결합체) 분야: 전통적 화학항암제와 다르게 종양세포만을 표적해 부작용을 감소시키고, 항체 치료제와는 차별적으로 약물을 접합시켜 치료 효과를 증진시킴, 합성신약 분야: 심각한 내성문제로 마땅한 치료제가 없는 그람음성균과 그람양성균 치료제를 개발중, 의약사업부문: 의료기기 및 의료소모품을 수도권 소재의 2개 병원에 납품 | N22: 암세포 표적 결합 기술 기반의 글로벌 링커·독성물질(Payload) 기술, 얀센 등 글로벌 빅파마 대상 대규모 기술이전 | O22: 영업 이익 적자 | P22: 반기보고서 | Q22: 탈락
B23: 휴젤 | C23: 145020 | D23: 235500 | E23: 2.947323 | F23: 0.00055337401 | G23: 0.054762166 | H23: 가능 | I23: 0.154 | J23: 0.4072 | K23: 0.0785 | L23: 29.75배/2.33배 | M23: 글로벌 메디컬 에스테틱 전문기업 Toxin: 보툴렉스, Filler & Skinbooster: 더채움, 바이리즌, Cosmetics: 웰라쥬, Thread: Blue Rose Forte 등, 기타: 용역 매출 등 | N23: 국내 톡신 시장 점유율 1위, 미국 FDA 승인 획득 및 중국·유럽 등 글로벌 3대 빅마켓 진출 완료 | O23: 보툴리눔 톡신 해외 진출 확대와 뛰어난 수익성 | P23: 반기보고서 | Q23: 보류
B24: SK바이오사이언스 | C24: 302440 | D24: 36750 | E24: 2.883278 | F24: 0.00054134925 | G24: 0.0085456884 | H24: 가능
B25: 보로노이 | C25: 310210 | D25: 141500 | E25: 2.621082 | F25: 0.0004921207 | G25: 0.032903807 | H25: 가능
B26: 한올바이오파마 | C26: 009420 | D26: 48600 | E26: 2.538895 | F26: 0.00047668969 | G26: 0.011301237 | H26: 가능
B27: 올릭스 | C27: 226950 | D27: 108300 | E27: 2.463883 | F27: 0.00046260583 | G27: 0.02518362 | H27: 가능
B28: 케어젠 | C28: 214370 | D28: 41350 | E28: 2.221115 | F28: 0.00041702498 | G28: 0.0096153528 | H28: 가능
B29: 디앤디파마텍 | C29: 347850 | D29: 46650 | E29: 2.138324 | F29: 0.00040148057 | G29: 0.010847792 | H29: 가능
B30: 클래시스 | C30: 214150 | D30: 31600 | E30: 2.061447 | F30: 0.00038704655 | G30: 0.0073481293 | H30: 가능
B31: 에스티팜 | C31: 237690 | D31: 89500 | E31: 1.868459 | F31: 0.00035081212 | G31: 0.020811949 | H31: 가능
B32: 셀트리온제약 | C32: 068760 | D32: 39250 | E32: 1.742792 | F32: 0.00032721754 | G32: 0.0091270277 | H32: 가능
B33: 네이처셀 | C33: 007390 | D33: 24850 | E33: 1.601211 | F33: 0.00030063503 | G33: 0.0057785131 | H33: 가능
B34: 씨젠 | C34: 096530 | D34: 32250 | E34: 1.507184 | F34: 0.00028298101 | G34: 0.0074992775 | H34: 가능
B35: 녹십자 | C35: 006280 | D35: 124900 | E35: 1.459649 | F35: 0.00027405609 | G35: 0.029043714 | H35: 가능
... B52: 앱클론 | C52: 174900 | D52: 20700 | E52: 0.413009 | F52: 7.7544417e-05 | G52: 0.0048134898 | H52: 가능
A54: 선정 결과
A55: Top 1 | B55: 삼성바이오로직스 | C55: 4공장 가동률 상승과 대형 CDMO 장기 계약 확대로 시장 컨센서스(영업이익률 ~40% 수준)를 웃도는 45.3%의 압도적 영업이익률 기록
A56: Top 2 | B56: 알테오젠 | C56: SC 제형 변경 플랫폼(ALT-B4) 기술이전 로열티 유입 본격화로 컨센서스를 뛰어넘는 52.3%의 영업이익률과 18.5%의 ROE 달성
A57: Top 3 | B57: 한미약품 | C57: 자체 개발 개량신약/복합제 판매 호조와 중국 자회사 실적 방어로 영업이익률 21.5% 기록, 시장 컨센서스에 부합하는 안정적 현금 창출력과 비만 파이프라인 모멘텀을 확보
A58: 탈락 1 | B58: HLB | C58: 영업이익 적자, 순이익 적자 (PBR 9.37배) (간암 신약 승인 재신청 이슈로 실적 기반의 펀더멘탈 지원이 부족)
A59: 탈락 2 | B59: 삼천당제약 | C59: PER 270.1배, ROE 3.3% (영업이익률 6.6%)(바이오시밀러 기대감 대비 밸류에이션 부담이 극심하고 수익성이 저해됨.)
A60: 탈락 3 | B60: 에이비엘바이오 | C60: 영업이익 적자, 순이익 적자 (PBR 18.92배) (이중항체 기술력 대비 밸류에이션이 높고 당장 실현되는 이익 지표가 부재)
...

Sheet 금융 — 보험·증권
A1: 금융 — 보험·증권
A2: ICOK Fund 26-2 · 담당 산업 스크리닝
A4: 팀 | B4: 팀 3 · 내수·디펜시브 | D4: 담당자 | E4: 조찬형 | G4: 제출일 | H4: 46286
A5: 지수 비중 | B5: 3.77% | D5: 배정액 | E5: 1,056,617원 | G5: 종목 수 | H5: 19 | J5: 기준일 | K5: 2026-09-15
A7: 보험은 IFRS17 기준 CSM을 확인한다.
A8: 음영 셀은 기입 완료. 흰색 셀만 작성한다.
A10: 하위 테마 | B10: 기업명 | C10: 코드 | D10: 주가 | E10: 시가총액(조) | F10: 지수 비중 | G10: 1주 / 팀예산 | H10: 매수 판정 | I10: 매출 CAGR(3Y) | J10: 영업이익률 | K10: ROE | L10: PER / PBR | M10: 주요 제품 | N10: 시장 포지셔닝 | O10: 투자포인트 / 탈락 사유 | P10: 출처 · 기준일 | Q10: 판정
A11: 생명보험 | B11: 삼성생명 | C11: 032830 | D11: 285500 | E11: 57.1 | F11: 0.010720798 | G11: 0.066388953 | H11: 가능 | I11: 0.0467 | J11: 0.0739 | K11: 0.0713 | L11: 13.69x / 0.40x | M11: 종신·건강·연금보험, 퇴직연금, 자산운용 | N11: 국내 최대권 생명보험사, 삼성그룹 금융계열 핵심 | O11: 압도적인 자본력과 브랜드, 안정적인 보장성·연금보험 기반. 다만 PER이 10배를 넘어 저평가 매력은 DB손보·현대해상보다 낮음. | P11: FnGuide·와이즈 리포트·Alpha Square·시장 자료 / 2026-09-15 | Q11: Top 2
A12: 손해보험 | B12: 삼성화재 | C12: 000810 | D12: 661000 | E12: 29.51198 | F12: 0.0055410156 | G12: 0.15370612 | H12: 가능 | I12: 0.0642 | J12: 0.1186 | K12: 0.1204 | L12: 14.50x / 0.75x | M12: 자동차·장기·일반보험, 재보험 | N12: 국내 대표 손해보험사, 손보업계 상위권 | O12: 높은 브랜드 신뢰도, 우수한 보험손익과 자본건전성, 자동차·장기보험 포트폴리오. 다만 PBR 1배 이상으로 보험업 평균 대비 밸류에이션 부담. | P12: FnGuide·와이즈 리포트·Alpha Square·시장 자료 / 2026-09-15 | Q12: 탈락 1
A13: 금융지주·보험/증권 | B13: 메리츠금융지주 | C13: 138040 | D13: 126500 | E13: 21.16943 | F13: 0.0039746619 | G13: 0.029415771 | H13: 가능 | I13: -0.055 | J13: 0.2048 | K13: 0.2249 | L13: 9.04x / 1.92x | M13: 메리츠화재, 메리츠증권, 기업금융·투자금융 | N13: 보험과 증권을 결합한 고ROE 금융지주 | O13: ROE 약 22.5%로 12개 종목 중 수익성 우수. 주주환원과 자본배분도 강점이나 PBR 약 2배로 높은 프리미엄이 이미 반영됨. | P13: FnGuide·와이즈 리포트·Alpha Square·시장 자료 / 2026-09-15 | Q13: 탈락 2
A14: 대형 종합 증권 | B14: 미래에셋증권 | C14: 006800 | D14: 32050 | E14: 17.403825 | F14: 0.0032676515 | G14: 0.0074527704 | H14: 가능 | I14: 0.4413 | J14: 0.0586 | K14: 0.198 | L14: 6.80x / 1.30x | M14: 위탁매매, IB, WM, 해외·대체투자, 자산관리 | N14: 글로벌·대체투자 역량을 갖춘 대형 증권사 | O14: 해외사업, WM, IB, 대체투자 및 자산관리 다변화. 반면 거래대금 감소와 금리 상승으로 3분기 실적 컨센서스 하향 위험이 존재. | P14: FnGuide·와이즈 리포트·Alpha Square·시장 자료 / 2026-09-15 | Q14: 보류
A15: 손해보험 | B15: DB손해보험 | C15: 005830 | D15: 188700 | E15: 12.359916 | F15: 0.0023206334 | G15: 0.043879494 | H15: 가능 | I15: 0.0496 | J15: 0.1241 | K15: 0.159 | L15: 6.80x / 0.90x | M15: 자동차·장기·일반보험 | N15: 수익성 중심의 대형 손해보험사 | O15: 높은 ROE와 낮은 PER의 조합이 매력적. 보험손익과 장기보험 수익성이 우수해 가치·수익성 균형이 좋음. | P15: FnGuide·와이즈 리포트·Alpha Square·시장 자료 / 2026-09-15 | Q15: Top 1
A16: 금융지주·증권 | B16: 한국금융지주 | C16: 071050 | D16: 191200 | E16: 10.65481 | F16: 0.0020004916 | G16: 0.044460833 | H16: 가능 | I16: 0.0874 | J16: 0.151 | K16: 0.231 | L16: 3.80x / 0.80x | M16: 한국투자증권, 자산운용, 저축은행, 벤처투자 | N16: 비은행 금융그룹 및 종합 투자금융 플랫폼 | O16: 증권·자산운용·벤처투자 사업을 보유해 자본시장 활황의 수혜 가능. PER 약 4.9배, 예상 배당수익률 6% 이상이라는 점은 긍정적이나 증시 거래대금 감소에 민감. | P16: FnGuide·와이즈 리포트·Alpha Square·시장 자료 / 2026-09-15 | Q16: Top 3
A17: 대형 종합 증권 | B17: NH투자증권 | C17: 005940 | D17: 25850 | E17: 9.543978 | F17: 0.0017919276 | G17: 0.0060110488 | H17: 가능 | I17: 0.1028 | J17: 0.0885 | K17: 0.1176 | L17: 7.20x / 0.90x | M17: 위탁매매, IB, WM, 연금·자산관리 | N17: 농협금융 계열 대형 종합증권사 | O17: IB, WM, 연금 부문과 농협 계열 네트워크가 강점. 다만 증권업 전반의 거래대금 감소와 금리 상승에 따른 실적 둔화 가능성. | P17: FnGuide·와이즈 리포트·Alpha Square·시장 자료 / 2026-09-15 | Q17: 보류
A18: 대형 종합 증권 | B18: 삼성증권 | C18: 016360 | D18: 86900 | E18: 7.76017 | F18: 0.0014570091 | G18: 0.020207356 | H18: 가능 | I18: 0.0813 | J18: 0.1096 | K18: 0.189 | L18: 5.00x / 0.90x | M18: 위탁매매, WM, IB, 운용상품 | N18: 고액자산가 중심의 WM 강자 | O18: WM 기반의 안정적인 수익구조, 삼성 브랜드, IB 확대가 강점. 그러나 삼성화재·DB손보 대비 PER이 높고 주가에 실적 기대가 반영됨. | P18: FnGuide·와이즈 리포트·Alpha Square·시장 자료 / 2026-09-15 | Q18: 보류
A19: 온라인 증권·브로커리지 | B19: 키움증권 | C19: 039490 | D19: 268500 | E19: 7.042303 | F19: 0.0013222261 | G19: 0.062435846 | H19: 가능 | I19: 0.0746 | J19: 0.0971 | K19: 0.24 | L19: 4.40x / 1.00x | M19: 온라인 주식매매, 신용융자, 해외주식, IB | N19: 개인투자자 중심 온라인 브로커리지 1위권 | O19: 높은 ROE와 개인 거래대금 증가의 직접적인 수혜. 그러나 브로커리지 의존도가 높아 거래대금 감소 시 이익 변동성이 큼. | P19: FnGuide·와이즈 리포트·Alpha Square·시장 자료 / 2026-09-15 | Q19: 보류
A20: 신용카드·소비자금융 | B20: 삼성카드 | C20: 029780 | D20: 45250 | E20: 5.242615 | F20: 0.00098432607 | G20: 0.010522242 | H20: 가능 | I20: 0.0228 | J20: 0.1676 | K20: 0.065 | L20: 10.00x / 0.70x | M20: 신용판매, 카드론, 할부금융, 회원서비스 | N20: 국내 대표 신용카드사 | O20: 안정적인 회원 기반과 높은 영업이익률, 배당 매력. 다만 가맹점 수수료 규제와 카드론 건전성, 소비 둔화가 부담. | P20: FnGuide·와이즈 리포트·Alpha Square·시장 자료 / 2026-09-15 | Q20: 탈락 3
A21: 생명보험 | B21: 한화생명 | C21: 088350 | D21: 5970 | E21: 5.185124 | F21: 0.00097353186 | G21: 0.0013882384 | H21: 가능 | I21: 0.0381 | J21: 0.0684 | K21: 0.062 | L21: 3.24x / 0.35x | M21: 종신·건강·연금보험, 퇴직연금 | N21: 대형 생명보험사, 한화금융그룹 핵심 | O21: 낮은 PBR과 금리·보장성보험 개선 기대. 다만 ROE와 자본효율성이 삼성생명·메리츠금융보다 낮고 생명보험 업종의 성장성이 제한적. | P21: FnGuide·와이즈 리포트·Alpha Square·시장 자료 / 2026-09-15 | Q21: 탈락 4
A22: 손해보험 | B22: 현대해상 | C22: 001450 | D22: 49200 | E22: 4.194214 | F22: 0.00078748376 | G22: 0.011440758 | H22: 가능 | I22: 0.0571 | J22: 0.1032 | K22: 0.138 | L22: 6.80x / 1.00x | M22: 자동차·장기·일반보험 | N22: 대형 손해보험사, 자동차·장기보험 중심 | O22: PER 약 3.0~3.8배, PBR 약 0.52~0.60배로 저평가. 다만 낮은 주주환원 여력과 자동차보험 손해율, 장기보험 손익 변동성이 할인요인. | P22: FnGuide·와이즈 리포트·Alpha Square·시장 자료 / 2026-09-15 | Q22: 탈락 5
B23: 서울보증보험 | C23: 031210 | D23: 42950 | E23: 2.998838 | F23: 0.00056304619 | G23: 0.0099874099 | H23: 가능
B24: 코리안리 | C24: 003690 | D24: 15020 | E24: 2.65435 | F24: 0.00049836692 | G24: 0.0034926868 | H24: 가능
B25: 미래에셋생명 | C25: 085620 | D25: 19280 | E25: 2.60627 | F25: 0.00048933967 | G25: 0.004483289 | H25: 가능
B26: 신영증권 | C26: 001720 | D26: 146200 | E26: 2.403528 | F26: 0.00045127389 | G26: 0.033996725 | H26: 가능
B27: 대신증권 | C27: 003540 | D27: 27000 | E27: 1.286985 | F27: 0.0002416376 | G27: 0.0062784649 | H27: 가능
B28: 한화투자증권 | C28: 003530 | D28: 4745 | E28: 1.018029 | F28: 0.00019113982 | G28: 0.0011033821 | H28: 가능
B29: 미래에셋벤처투자 | C29: 100790 | D29: 16020 | E29: 0.850992 | F29: 0.00015977782 | G29: 0.0037252225 | H29: 가능
A31: 선정 결과
A32: Top 1 | B32: DB손해보험 | C32: 2026E ROE 15.90%, PER 6.80x, PBR 0.90x로 수익성과 밸류에이션의 균형이 가장 우수하다. 손해보험업의 안정적인 보험손익과 장기보험 수익성을 고려할 때, 내수·디펜시브 포트폴리오의 핵심 종목으로 판단한다.
A33: Top 2 | B33: 삼성생명 | C33: 2026E ROE 7.13%로 수익성은 높지 않지만, 대형 생명보험사 중 최고 수준의 자본력과 브랜드 경쟁력을 보유했다. 보장성보험·연금보험·퇴직연금 중심의 안정적인 사업구조가 내수·디펜시브 전략과 부합한다
A34: Top 3 | B34: 한국금융지주 | C34: 2026E ROE 23.10%, PER 3.80x, PBR 0.80x로 수익성 대비 밸류에이션이 낮다. 증권 외에도 자산운용·저축은행·벤처투자 사업을 보유해 사업 포트폴리오가 다변화되어 있다.
A35: 탈락 1 | B35: 삼성화재 | C35: 2026E ROE는 12.04%로 양호하지만 PER 14.50x로 DB손해보험의 6.80x보다 높다. 높은 시장 지위와 안정성은 긍정적이나, 브랜드 프리미엄과 우수한 보험손익이 현재 주가에 상당 부분 반영된 것으로 판단한다.
A36: 탈락 2 | B36: 메리츠금융지주 | C36: 2026E ROE는 22.49%로 우수하지만 PBR이 1.92x로 높고 매출 CAGR은 -5.50%다. 수익성은 뛰어나지만 밸류에이션 부담과 외형 성장성 부족을 고려해 제외한다.
A37: 탈락 3 | B37: 삼성카드 | C37: 2026E 영업이익률은 16.76%로 높지만 ROE는 6.50%에 그치고 PER은 10.00x다. 높은 이익률에 비해 자본효율성이 낮으며, DB손해보험·한국금융지주보다 성장성과 수익성의 조합이 약하다.
A38: 탈락 4 | B38: 한화생명 | C38: 2026E PER 3.24x, PBR 0.35x로 저평가되어 있지만 ROE는 6.20%로 낮다. 낮은 밸류에이션이 자본효율성 부족을 반영하고 있어 삼성생명보다 우선 선정할 근거가 부족하다.
A39: 탈락 5 | B39: 현대해상 | C39: 13.80%, PER 6.80x, PBR 1.00x로 지표는 양호하지만 DB손해보험보다 PER·PBR 매력이 낮다. 손해보험업 내 수익성과 밸류에이션 모두 DB손해보험을 앞서지 못해 최종 선정에서 제외한다.

Sheet 금융 — 은행·지주
A1: 금융 — 은행·지주
A2: ICOK Fund 26-2 · 담당 산업 스크리닝
A4: 팀 | B4: 팀 3 · 내수·디펜시브 | D4: 담당자 | E4: 고낭균 | G4: 제출일 | H4: 46281
A5: 지수 비중 | B5: 4.12% | D5: 배정액 | E5: 1,152,566원 | G5: 종목 수 | H5: 9 | J5: 기준일 | K5: 2026-09-15
A7: 매출·영업이익률 대신 NIM·대손비용률·CET1·주주환원율을 사용한다. 밸류에이션은 PBR-ROE 기준.
A8: 음영 셀은 기입 완료. 흰색 셀만 작성한다.
A10: 하위 테마 | B10: 기업명 | C10: 코드 | D10: 주가 | E10: 시가총액(조) | F10: 지수 비중 | G10: 1주 / 팀예산 | H10: 매수 판정 | I10: 매출 CAGR(3Y) | J10: 영업이익률 | K10: ROE | L10: PER / PBR | M10: 주요 제품 | N10: 시장 포지셔닝 | O10: 투자포인트 / 탈락 사유 | P10: 출처 · 기준일 | Q10: 판정
A11: 종합금융 / 금융지주, 은행·증권·보험·카드 등 비은행 포트폴리오 확대, 자본시장 중심 성장, 생산적 금융, 자동차·부동산·헬스케어 등 비금융 영역 확장 | B11: KB금융 | C11: 105560 | D11: 175800 | E11: 62.354104 | F11: 0.011707282 | G11: 0.039973783 | H11: 가능 | I11: 81263303000 | J11: 8.7221312 | K11: 3.1709584 | L11: 9.235 / 0.885 | M11: ㆍKB국민은행: 예금·대출·외환·신탁·연금·투신·방카슈랑스 등 ㆍKB증권: 투자매매·중개·자문·일임·신탁·사모펀드 등 ㆍKB손해보험: 자동차·장기·일반보험 ㆍKB국민카드: 신용·체크카드, 일반대출, 할부금융 | N11: 국내 최대 고객 기반을 보유한 종합금융그룹으로, 은행과 비은행의 균형 잡힌 포트폴리오를 기반으로 국내 금융산업을 선도. KB국민은행은 시중은행 수위권의 자산·대출·예수부채 규모를 유지하고 있으며, 비은행 부문과 자본시장 확대를 통해 성장 영역을 넓히는 전략 | O11: 국내 최대 고객 기반과 은행·증권·보험·카드의 균형 잡힌 포트폴리오가 강점. 다만 PER 9.24배, PBR 0.89배로 비교군 대비 밸류에이션 부담 | P11: 반기보고서 (2026.06) | Q11: 탈락
A12: 종합금융 / 금융지주, 은행·카드·증권·보험·캐피탈 등 다각화된 금융 포트폴리오, 자산운용·부동산·벤처투자·금융IT 등 금융 연계 사업 확장 | B12: 신한지주 | C12: 055550 | D12: 112200 | E12: 52.672317 | F12: 0.0098894797 | G12: 0.025512278 | H12: 가능 | I12: 5.9393035e+10 | J12: 15.516877 | K12: 2.8193261 | L12: 8.465 / 0.725 | M12: ㆍ신한은행·제주은행: 예금·대출 ㆍ신한카드: 신용카드·카드대출·할부금융·리스 ㆍ신한투자증권: 유가증권 매매·중개·인수 ㆍ신한라이프·신한EZ손해보험: 생명·손해보험 ㆍ신한캐피탈: 시설대여·신기술사업금융 ㆍ그 외 자산운용·저축은행·부동산신탁·REITs·벤처투자·금융IT | N12: 은행을 핵심 수익원으로 하면서 비은행 사업을 폭넓게 보유한 종합금융그룹. 2026년 반기 순이익의 70.2%가 은행 부문에서 발생하며, 증권·카드·보험 등 비은행 부문이 수익원을 보완하는 구조. 다각화된 사업 포트폴리오와 위험관리 역량을 기반으로 안정적인 실적을 추구 | O12: 영업이익률 15.52%와 안정적인 은행 기반, 증권·카드·보험 등 균형 잡힌 사업 포트폴리오를 보유. PER 8.47배, PBR 0.73배로 수익성·안정성·밸류에이션의 균형이 우수 | P12: 반기보고서 (2026.06) | Q12: 매수
A13: 종합금융 / 금융지주, 은행 중심의 안정적 수익 기반 + 증권·카드·캐피탈·보험 등 비은행 강화, 글로벌 금융, 디지털 금융, 대체투자·벤처투자 등 신성장 영역 확대 | B13: 하나금융지주 | C13: 086790 | D13: 137600 | E13: 37.28546 | F13: 0.0070005237 | G13: 0.031287784 | H13: 가능 | I13: 7.3417168e+10 | J13: 5.7727807 | K13: 2.567988 | L13: 7.565 / 0.64 | M13: ㆍ하나은행: 예·적금, 대출, 외환, 신탁, PB, 투자금융 ㆍ하나증권: WM·IB·S&T ㆍ하나카드: 신용판매·카드대출·할부금융, 원더카드·트래블로그 ㆍ하나캐피탈: 할부·리스·기업금융·렌터카 ㆍ하나생명·하나손해보험: 생명·손해보험 ㆍ그 외 저축은행, 부동산신탁, NPL, 대체투자, 벤처투자, 금융IT | N13: 은행을 핵심으로 하면서 비은행·글로벌·대체투자까지 사업영역을 다변화하는 종합금융그룹. 특히 하나증권의 WM·IB·S&T 균형, 하나카드의 트래블로그, 하나대체투자자산운용의 대체투자 등 계열사별 전문성을 활용해 비은행 경쟁력을 확대. 하나은행은 국내 610개·해외 114개 지점을 기반으로 글로벌 네트워크를 보유 | O13: PER 7.57배, PBR 0.64배로 대형 금융지주 중 밸류에이션 매력이 높음. 은행 기반에 비은행·글로벌·대체투자를 확대하고 있어 저평가 + 성장성을 동시에 기대 | P13: 반기보고서 (2026.06) | Q13: 메수
A14: 종합금융 / 금융지주, 은행 중심에서 증권·보험·자산운용 등 비은행 강화, 기업금융·생산적 금융, 자본시장, 디지털·AI 금융 | B14: 우리금융지주 | C14: 316140 | D14: 36350 | E14: 26.782191 | F14: 0.0050284846 | G14: 0.0082653413 | H14: 가능 | I14: 43383792000 | J14: 7.4863557 | K14: 2.0621218 | L14: 7.155 / 0.58 | M14: ㆍ우리은행: 예금·대출 등 은행업 ㆍ우리투자증권: 증권·자본시장 ㆍ동양생명·ABL생명: 생명보험 ㆍ우리카드: 카드·금융 ㆍ우리금융캐피탈: 여신전문금융 ㆍ우리벤처파트너스·우리프라이빗에퀴티자산운용: 벤처·PE 투자 | N14: 은행 중심에서 증권·보험을 확보하며 종합금융그룹으로 전환한 후발주자. 2024년 우리투자증권 출범, 2025년 동양생명·ABL생명 편입을 통해 비은행 포트폴리오를 빠르게 확장. 기업금융·생산적 금융을 핵심 성장축으로 삼는 동시에 비은행 부문 기여도를 높여 은행 의존도를 낮추고 ROE를 개선하는 전략 | O14: PER 7.16배, PBR 0.58배로 저평가 매력이 높고 증권·보험 편입을 통한 비은행 확대 가능성이 있음. 그러나 ROE 2.06%로 비교군 대비 낮아 수익성 개선 확인이 필요 | P14: 반기보고서 (2026.06) | Q14: 탈락
A15: 중소기업 금융 / 정책금융 / 종합금융. 중소기업·소상공인 금융을 핵심으로 하면서 증권·캐피탈 등 비은행, 해외금융, 생산적 금융까지 확장 | B15: 기업은행 | C15: 024110 | D15: 20350 | E15: 16.227616 | F15: 0.0030468126 | G15: 0.0046272268 | H15: 가능 | I15: 30090364000 | J15: 9.8016678 | K15: 1.9204688 | L15: 6.215 / 0.44 | M15: ㆍ기업은행: 예금·적금, 기업대출, 어음할인, 외환, 파생상품, 유가증권, 투자자문, 신탁, 보험대리, 퇴직연금, 신용카드 등 ㆍIBK캐피탈·IBK투자증권 등: 여신·캐피탈 및 증권업 ㆍ해외법인·지점: 중국·인도네시아·미얀마·폴란드 등 해외 금융 | N15: 중소기업 금융시장 특화 리딩뱅크. 2026년 6월 기준 중소기업대출 잔액 270.0조원, 시장점유율 24.6%로 중소기업 금융시장을 선도. 단순 대출 공급을 넘어 기술력·성장가능성을 반영한 여신, 모험자본, 성장단계별 지원, ESG 지원 등을 통해 중소기업의 성장 파트너이자 정책금융·생산적 금융의 핵심 역할을 지향 | O15: 중소기업대출 시장점유율 24.6%의 확고한 시장지위와 PER 6.22배, PBR 0.44배의 저평가가 강점. 다만 정책금융기관 특성상 성장성과 재평가 폭에 한계 | P15: 반기보고서 (2026.06) | Q15: 탈락
A16: 인터넷전문은행 / 디지털 금융 / 금융 플랫폼. 비대면·모바일 중심의 은행업을 기반으로 금융과 생활 영역을 연결하는 플랫폼 사업으로 확장 | B16: 카카오뱅크 | C16: 323410 | D16: 21150 | E16: 10.091097 | F16: 0.0018946518 | G16: 0.0048091326 | H16: 가능 | I16: 2.8419857e+09 | J16: 21.330315 | K16: 2.4664102 | L16: 19.93 / 1.605 | M16: ㆍ뱅킹 비즈니스: 예금·적금, 대출 등 기본 여수신 상품 및 은행 금융서비스 ㆍ플랫폼 비즈니스: 모바일 앱 기반 금융서비스, 금융·생활 영역의 다양한 제휴 서비스 | N16: 모바일 기반 디지털 금융 혁신 플랫폼. 오프라인 점포 없이 100% 모바일 UX와 IT 기술을 활용해 비용 효율성과 고객 편의성을 동시에 추구하며, 기존 은행과 차별화된 사용자 경험과 상품·혜택을 제공. 금융업을 넘어 비금융 파트너와의 제휴를 통해 금융+생활 플랫폼으로 확장하는 전략 | O16: 영업이익률 21.33%와 디지털 금융 플랫폼으로서의 성장성은 강점이나 PER 19.93배, PBR 1.61배로 금융주 중 밸류에이션 부담이 가장 높음. 또한 카카오AI·카카오X 사업부 분할에 따른 사업구조 변화 및 불확실성이 존재하며, 카카오AI에 대한 성장 기대가 카카오 계열 전반의 가치에 반영되면서 현재 주가가 AI 성장성을 선반영해 고평가되었을 가능성도 고려할 필요 | P16: 반기보고서 (2026.06) | Q16: 탈락
A17: 종합금융 / 지방금융 / 은행·캐피탈 중심 금융지주. 전북은행·광주은행을 기반으로 캐피탈·자산운용·신기술금융 및 동남아 금융으로 사업 다각화 | B17: JB금융지주 | C17: 175330 | D17: 32200 | E17: 6.006003 | F17: 0.0011276558 | G17: 0.0073217054 | H17: 가능 | I17: 4482707000 | J17: 21.250376 | K17: 3.189594 | L17: 7.225 / 0.845 | M17: ㆍ전북은행·광주은행: 은행업 ㆍJB우리캐피탈: 여신전문금융 ㆍJB자산운용: 집합투자·자산운용 ㆍJB인베스트먼트: 신기술사업금융 ㆍPPCBank: 캄보디아 은행 ㆍJB PPAM: 캄보디아 자산운용 ㆍJB Capital Myanmar: 미얀마 소액대출 ㆍJB Securities Vietnam: 베트남 증권 | N17: 서남권 대표 종합금융그룹이자 고수익성 강소 금융그룹. 전북은행·광주은행의 지역 기반에 JB우리캐피탈을 결합해 수익원을 다각화하고 있으며, 특히 JB우리캐피탈이 그룹 실적을 견인. 국내 지역금융을 기반으로 캄보디아·미얀마·베트남 등 해외 금융사업도 운영. 규모 확대보다는 경영체질 개선·비용 효율화·리스크 관리·높은 수익성을 통한 차별화를 추구 | O17: ROE 3.19%, 영업이익률 21.25%로 높은 수익성을 보유하면서 PER 7.23배, PBR 0.85배로 평가. 수익성 대비 밸류에이션 매력이 가장 뚜렷함 | P17: 반기보고서 (2026.06) | Q17: 매수
A18: 지방금융 / 종합금융 / 지역밀착 금융 / 디지털·생산적 금융. 부산·경남 지역은행을 기반으로 캐피탈·증권·저축은행·자산운용·벤처투자 등으로 사업 다각화하고, 지역특화산업·AI·디지털·글로벌 금융으로 확장 | B18: BNK금융지주 | C18: 138930 | D18: 16040 | E18: 4.92171 | F18: 0.00092407462 | G18: 0.0036472098 | H18: 가능 | I18: 9.9493717e+09 | J18: 7.4224987 | K18: 1.860636 | L18: 6.825 / 0.495 | M18: ㆍ부산은행·경남은행: 은행업 ㆍBNK캐피탈: 여신전문금융 ㆍBNK투자증권: 금융투자 ㆍBNK저축은행: 저축은행 ㆍBNK자산운용: 자산운용 ㆍBNK벤처투자: 창업·벤처투자 ㆍ이외 신용조사·추심대행, 시스템 공급·개발 등 | N18: 부산·경남을 중심으로 한 국내 대표 지역 종합금융그룹. 383개 국내 점포와 66개 해외 거점을 기반으로 지역금융에서 글로벌 금융으로 확장. 은행부문 경쟁력을 유지하면서 비은행·비이자 수익을 확대하고 있으며, 특히 지역특화산업 지원 + 생산적 금융 + AI·디지털금융을 차별화된 성장축으로 설정. 장기적으로 수도권·글로벌 사업과 신사업을 확대해 지역금융그룹의 성장 한계를 보완하려는 전략 | O18: PER 6.83배, PBR 0.50배로 저평가 매력이 있으나 ROE 1.86%로 낮음. 낮은 밸류에이션이 저평가보다는 수익성에 대한 할인일 가능성이 존재 | P18: 반기보고서 (2026.06) | Q18: 탈락
A19: 지방금융 → 전국 종합금융 / 하이브리드 금융 / 디지털·글로벌 금융. 은행을 중심으로 증권·보험·캐피탈·자산운용·핀테크 등 금융 전 영역으로 다각화하고 수도권·해외로 사업 확장 | B19: iM금융지주 | C19: 139130 | D19: 18300 | E19: 2.89805 | F19: 0.00054412276 | G19: 0.0041610934 | H19: 가능 | I19: 7.9676275e+09 | J19: 5.0027646 | K19: 2.3260786 | L19: 6.22 / 0.425 | M19: ㆍiM뱅크: 예·적금, 대출, 지급결제, 외환, 신탁, 카드, WM, CIB, 디지털금융 ㆍiM증권: 리테일·브로커리지, 홀세일, IB, 자산운용, PI, 퇴직연금, 신탁, 랩, 리서치 ㆍiM라이프생명보험: 생명보험 ㆍiM캐피탈: 리스·할부금융·대출·렌탈 ㆍiM에셋자산운용: 주식·채권·대체투자 및 투자자문·일임 ㆍ그 외 유페이·데이터시스템·신용정보·투자파트너스·뉴지스탁 및 동남아 금융사업 | N19: 지역은행에서 전국 단위 종합금융그룹으로 전환 중인 하이브리드 금융그룹. iM뱅크의 시중은행 전환을 기반으로 수도권 등 전국 영업망을 확대하고, 디지털 플랫폼과 오프라인 채널을 결합한 하이브리드 금융을 차별화 전략으로 추진. 동시에 증권·보험·캐피탈·자산운용 등 계열사 간 시너지를 강화하고 캄보디아·미얀마·라오스 등 해외시장으로 성장 기반을 확대 | O19: PER 6.22배, PBR 0.43배로 저평가되어 있으나 영업이익률 5.00%로 수익성이 비교군 대비 낮음. 시중은행 전환 및 전국화 전략의 성과가 아직 충분히 검증되지 않음 | P19: 반기보고서 (2026.06) | Q19: 탈락
A21: 선정 결과
A22: Top 1 | B22: 하나금융지주 | C22: 시장에서 대형 금융지주의 안정성을 공통적으로 긍정 평가하는 가운데, PER 7.57배·PBR 0.64배로 상대적으로 낮은 밸류에이션에 주목. 은행 중심의 안정성에 더해 비은행·글로벌·대체투자 확대가 진행되고 있어 저평가와 성장성을 동시에 확보할 가능성이 있다고 판단.
A23: Top 2 | B23: 신한지주 | C23: 은행 중심의 안정적 수익구조라는 시장의 평가에 더해, 영업이익률 15.52%와 PER 8.47배·PBR 0.73배의 균형적인 지표를 긍정적으로 평가. 증권·카드·보험 등 비은행 사업이 수익원을 보완하고 있어 수익성과 사업 다각화가 밸류에이션 부담을 상쇄할 수 있다고 판단.
A24: Top 3 | B24: JB금융지주 | C24: 지방금융이라는 규모의 한계가 상대적으로 부각될 수 있으나, ROE 3.19%·영업이익률 21.25%로 높은 수익성을 보유. PER 7.23배·PBR 0.85배로 높은 수익성에 비해 시장에서 충분히 프리미엄을 받지 못하고 있다고 판단하여 선정.
A25: 탈락 1 | B25: 카카오뱅크 | C25: 디지털 금융 플랫폼의 성장성은 긍정적이나 PER 19.93배·PBR 1.61배로 금융주 중 밸류에이션 부담이 가장 높음. 특히 카카오AI·카카오X 사업부 분할에 따른 사업구조 변화와 AI 부문에 대한 기대가 주가에 선반영되어 고평가되었을 가능성을 고려해 탈락.
A26: 탈락 2 | B26: KB끔융 | C26: 국내 최대 금융그룹이라는 안정성과 비은행 포트폴리오 확대는 긍정적이나, PER 9.24배·PBR 0.89배로 선정 기업 대비 밸류에이션 부담이 존재. 높은 시장 지위가 이미 주가에 상당 부분 반영되어 있어 추가적인 상승 여력이 상대적으로 제한적이라고 판단.
A27: 탈락 3 | B27: 우리금융지주 | C27: 증권·보험 편입으로 비은행 확대라는 성장 모멘텀이 있으나, ROE 2.06%로 선정 기업 대비 수익성이 낮은 수준. PER 7.16배·PBR 0.58배의 저평가 매력은 있으나 비은행 확대가 실제 수익성 개선으로 이어지는지 확인이 필요하다고 판단.
A28: 탈락 4 | B28: 기업은행 | C28: 중소기업 금융시장 점유율 24.6%와 PER 6.22배·PBR 0.44배의 저평가는 긍정적이나, 정책금융기관이라는 사업 특성상 성장성에 한계. 따라서 낮은 밸류에이션이 충분한 성장 기대를 반영하지 못한 기회라기보다 구조적인 할인 요인일 가능성을 고려해 탈락.
A29: 탈락 5 | B29: iM금융지주 | C29: 시중은행 전환과 전국화라는 성장 가능성에도 불구하고 영업이익률 5.00%로 비교군 중 수익성이 낮은 편. PER 6.22배·PBR 0.43배의 저평가 매력보다 전환 전략의 실적 기여가 아직 충분히 검증되지 않았다는 점을 더 크게 평가.

Sheet 통신·미디어·엔터
A1: 통신·미디어·엔터
A2: ICOK Fund 26-2 · 담당 산업 스크리닝
A4: 팀 | B4: 팀 3 · 내수·디펜시브 | D4: 담당자 | E4: 이서현 | G4: 제출일 | H4: 46287
A5: 지수 비중 | B5: 1.11% | D5: 배정액 | E5: 309,664원 | G5: 종목 수 | H5: 13 | J5: 기준일 | K5: 2026-09-15
A7: 음영 셀은 기입 완료. 흰색 셀만 작성한다.
A9: 하위 테마 | B9: 기업명 | C9: 코드 | D9: 주가 | E9: 시가총액(조) | F9: 지수 비중 | G9: 1주 / 팀예산 | H9: 매수 판정 | I9: 매출 CAGR(3Y) | J9: 영업이익률 | K9: ROE | L9: PER / PBR | M9: 주요 제품 | N9: 시장 포지셔닝 | O9: 투자포인트 / 탈락 사유 | P9: 출처 · 기준일 | Q9: 판정
A10: 통신 | B10: SK텔레콤 | C10: 017670 | D10: 88000 | E10: 18.901525 | F10: 0.0035488518 | G10: 0.02000963 | H10: 가능 | I10: -0.004 | J10: 0.0628 | K10: 0.0333 | L10: 46.3배 / 1.22배 | M10: 1. 이동통신(5G)·초고속인터넷 2. IPTV(SK브로드밴드+M14) 3. AI 데이터센터 | N10: 국내 이동통신 1위 사업자. 이동전화 점유율 47.7%로 1위, 초고속인터넷 28.8%로 2위를 차지하며 무선과 유선을 모두 갖춘 통신 대표 기업 | O10: 2025년 해킹사고로 영업이익이 41.1% 줄어 PER 46.3배는 일시적으로 높은 숫자. 2026년 상반기 영업이익 11,036억원(+21.9%)으로 회복 중. 다만 매출 CAGR -0.4%로 성장은 정체 | P10: DART 2025 사업보고서·2024 사업보고서·2026 반기보고서 | Q10: Top2
A11: 통신 | B11: KT | C11: 030200 | D11: 53000 | E11: 13.357149 | F11: 0.0025078687 | G11: 0.012051254 | H11: 가능 | I11: 0.0326 | J11: 0.0874 | K11: 0.1022 | L11: 7.7배 / 0.72배 | M11: 1. 이동통신·초고속인터넷·IPTV 2. 기업(B2B)·클라우드/IDC 3. 부동산 | N11: 초고속인터넷 40.1%·시내전화 79.0%로 유선 1위, 이동전화 28.4%로 2위. 통신에 더해 클라우드·데이터센터·부동산까지 사업을 넓힌 종합 ICT 기업 | O11: 배당 확대(주당 2,400원)·자사주 매입 등 주주환원이 강점. 다만 2025년 이익에 아파트 분양 일회성 수익이 섞여 2026년 상반기 영업이익 -33.6% | P11: DART 2025 사업보고서·2024 사업보고서·2026 반기보고서 | Q11: 보류
A12: 엔터·음악 | B12: 하이브 | C12: 352820 | D12: 173100 | E12: 7.461793 | F12: 0.0014009874 | G12: 0.039359851 | H12: 가능 | I12: 0.1427 | J12: 0.0186 | K12: -0.0733 | L12: 적자 / 2.17배 | M12: 1. 음반·음원 2. 공연 3. MD/라이선싱 4. 위버스(팬 플랫폼) | N12: 써클차트 Top100 앨범 판매량의 41.3%를 소속 아티스트가 차지하는 K-POP 기획사. 여러 레이블을 거느린 멀티 레이블 체제와 팬 플랫폼 위버스를 함께 운영 | O12: 매출은 연평균 14.3% 늘었지만 영업이익률 1.9%, ROE -7.3%로 이익이 거의 없음. 2026년 상반기도 매출 +78.1%에 영업손실 257억원 | P12: DART 2025 사업보고서·2024 사업보고서·2026 반기보고서 | Q12: 탈락
A13: 통신 | B13: LG유플러스 | C13: 032640 | D13: 14850 | E13: 6.302752 | F13: 0.0011833719 | G13: 0.003376625 | H13: 가능 | I13: 0.0358 | J13: 0.0577 | K13: 0.0601 | L13: 12.0배 / 0.69배 | M13: 1. 이동통신(무선) 2. 스마트홈(IPTV·인터넷) 3. 기업인프라(IDC 등) | N13: 이동전화 점유율 23.9%로 통신 3사 중 3위지만, 5G 핸셋 비중이 84.9%로 고객 대부분이 5G를 사용. 파주에 AI 데이터센터(AIDC)를 짓는 등 AI 인프라로 사업을 넓히는 중 | O13: PBR 0.69배로 순자산보다 주가 총액이 낮은 수준. 2026년 상반기 영업이익 6,167억원(+10.1%)으로 통신 3사 중 증가율 2위. 다만 ROE 6.0%로 KT(10.2%)보다 수익성은 낮음 | P13: DART 2025 사업보고서·2024 사업보고서·2026 반기보고서 | Q13: Top1
A14: 카지노·레저 | B14: 강원랜드 | C14: 035250 | D14: 14730 | E14: 3.151344 | F14: 0.00059167993 | G14: 0.0033493391 | H14: 가능 | I14: 0.0514 | J14: 0.1593 | K14: 0.0811 | L14: 9.9배 / 0.81배 | M14: 1. 내국인 출입 카지노(2025년 매출 89%) 2. 하이원리조트(호텔·콘도·스키·골프, 11%) | N14: 폐광지역특별법에 따라 국내에서 유일하게 내국인이 출입할 수 있는 카지노. 경쟁자가 없는 대신 영업장 면적·게임기구 수를 정부 허가로 정하는 규제 산업 | O14: 영업이익률 15.9%에 빚도 적은 편(부채비율 22.2%). 다만 성장이 느리고(CAGR 5.1%) 2026년 상반기 영업이익 -15.1% | P14: DART 2025 사업보고서·2024 사업보고서·2026 반기보고서 | Q14: 보류
A15: 미디어·광고·콘텐츠 | B15: 제일기획 | C15: 030000 | D15: 18790 | E15: 2.161625 | F15: 0.00040585544 | G15: 0.0042725107 | H15: 가능 | I15: 0.0225 | J15: 0.0741 | K15: 0.137 | L15: 10.4배 / 1.34배 | M15: 1. 광고 기획·제작 2. 매체 대행·프로모션 3. 디지털(AdTech) 솔루션 | N15: 46개국 55개 거점을 둔 글로벌 광고회사. 2026년 상반기 영업총이익의 78.9%를 해외에서 벌 만큼 해외 비중이 큼 | O15: ROE 13.7%로 수익성은 양호. 다만 매출 CAGR 2.2%로 성장이 느리고 2026년 상반기 영업이익 -14.2% | P15: DART 2025 사업보고서·2024 사업보고서·2026 반기보고서 | Q15: 탈락
A16: 엔터·음악 | B16: 에스엠 | C16: 041510 | D16: 87500 | E16: 2.003285 | F16: 0.00037612635 | G16: 0.019895939 | H16: 가능 | I16: 0.1136 | J16: 0.1558 | K16: 0.4165 | L16: 5.8배 / 1.94배 | M16: 1. 음반·음원·공연·MD(엔터 93.8%) 2. 광고(4.5%) 3. 팬 플랫폼(디어유) | N16: RIIZE·NCT WISH·aespa 등 여러 세대의 아티스트를 보유한 K-POP 기획사. 2026년 상반기 매출 중 음반·음원 23.7%, 공연·영상 등 58.6%로 공연 비중이 큼 | O16: 2026년 상반기 매출 +17.7%·영업이익 +14.0%로 성장 지속. 다만 PER 5.8배는 일회성 이익 2,140억원이 섞인 숫자로, 이를 빼면 PER 15.0배 | P16: DART 2025 사업보고서·2024 사업보고서 정정·2026 반기보고서 | Q16: Top3
A17: 엔터·음악 | B17: JYP Ent. | C17: 035900 | D17: 39150 | E17: 1.391097 | F17: 0.00026118512 | G17: 0.0089020113 | H17: 가능 | I17: 0.3344 | J17: 0.1889 | K17: 0.2921 | L17: 8.7배 / 2.14배 | M17: 1. 음반·음원 2. 공연 3. MD 4. IP 라이선싱 | N17: TWICE·Stray Kids·NMIXX 등을 보유한 K-POP 기획사. 아티스트별 레이블 체제와 자체 제작 인프라를 갖춰 음악을 꾸준히 만들어내는 구조 | O17: 매출 CAGR 33.4%·영업이익률 18.9%로 엔터 4사 중 수익성 1위. 다만 2026년 상반기 영업이익 -11.3%로 둔화 | P17: DART 2025 사업보고서·2024 사업보고서·2026 반기보고서 | Q17: 보류
A18: 카지노·레저 | B18: 롯데관광개발 | C18: 032350 | D18: 11680 | E18: 0.931193 | F18: 0.00017483594 | G18: 0.0026558236 | H18: 가능 | I18: 0.5266 | J18: 0.2193 | K18: 0.0806 | L18: 33.5배 / 2.47배 | M18: 1. 제주 드림타워 복합리조트(그랜드 하얏트 1,600실) 2. 외국인전용 카지노 3. 여행업 | N18: 제주 최대 규모 복합리조트인 드림타워를 운영하며 호텔·카지노·쇼핑을 한곳에서 제공. 2025년 카지노 이용객은 59만명 | O18: 매출 CAGR 52.7%·2026년 상반기 영업이익 +74.9%로 성장이 가장 빠른 편. 다만 부채비율 489%(13종목 중 최고)로 영업이익 1,433억원 중 지배순이익은 278억원 | P18: DART 2025 사업보고서·2024 사업보고서·2026 반기보고서 | Q18: 보류
A19: 카지노·레저 | B19: 파라다이스 | C19: 034230 | D19: 9880 | E19: 0.915178 | F19: 0.00017182905 | G19: 0.0022465357 | H19: 가능 | I19: 0.2508 | J19: 0.1355 | K19: 0.0562 | L19: 9.7배 / 0.52배 | M19: 1. 외국인전용 카지노 4곳(워커힐·인천·부산·제주) 2. 호텔(부산·파라다이스시티) | N19: 외국인만 출입할 수 있는 카지노를 운영하며, 인천 영종도에 호텔·카지노를 합친 복합리조트 파라다이스시티를 보유 | O19: PBR 0.52배·PER 9.7배로 주가가 낮은 편. 다만 2026년 상반기 매출 +7.8%에도 영업이익 -27.2% | P19: DART 2025 사업보고서·2024 사업보고서 정정·2026 반기보고서 | Q19: 보류
A20: 엔터·음악 | B20: 와이지엔터테인먼트 | C20: 122870 | D20: 44600 | E20: 0.833621 | F20: 0.00015651633 | G20: 0.010141244 | H20: 가능 | I20: 0.1172 | J20: 0.1308 | K20: 0.074 | L20: 22.6배 / 1.60배 | M20: 1. 음반·음원 2. 공연 3. 매니지먼트 4. MD | N20: 트레저의 일본 단독공연 누적 관객 100만명, 로제 'APT.'의 글로벌 싱글 1위(IFPI 2025) 등 해외 인지도가 높은 아티스트를 보유한 K-POP 기획사 | O20: PER 22.6배로 주가 부담이 크고 ROE 7.4%로 수익성은 낮음. 영업이익이 2023~2025년 869억원 → -206억원 → 713억원으로 크게 흔들림 | P20: DART 2025 사업보고서 정정·2024 사업보고서·2026 반기보고서 | Q20: 탈락
A21: 미디어·광고·콘텐츠 | B21: CJ ENM | C21: 035760 | D21: 38000 | E21: 0.833308 | F21: 0.00015645757 | G21: 0.0086405219 | H21: 가능 | I21: 0.0233 | J21: 0.0259 | K21: 0.0106 | L21: 28.2배 / 0.29배 | M21: 1. 미디어플랫폼(tvN·티빙) 2. 영화·드라마 3. 음악(Mnet) 4. 커머스 | N21: tvN·Mnet 등 여러 케이블 채널을 가진 방송채널사업자(MPP)로 시청점유율 14.9%의 1위. 다만 2022년 17.1%에서 점유율이 낮아지는 추세 | O21: PBR 0.29배로 주가는 매우 낮지만 영업이익률 2.6%·ROE 1.1%로 버는 돈이 적고, 부채비율 151.5%로 빚도 많음 | P21: DART 2025 사업보고서·2024 사업보고서·2026 반기보고서 | Q21: 탈락
A22: 미디어·광고·콘텐츠 | B22: 스튜디오드래곤 | C22: 253450 | D22: 21950 | E22: 0.659784 | F22: 0.00012387761 | G22: 0.0049910383 | H22: 가능 | I22: -0.0873 | J22: 0.0572 | K22: 0.0134 | L22: 63.9배 / 0.85배 | M22: 1. 드라마 기획·제작 2. 방송사 편성(21.3%) 3. 국내외 판권 판매(77.0%) | N22: CJ ENM 계열의 드라마 제작사로, 만든 드라마를 방송사와 OTT에 공급. 2026년에는 지상파 3사로 편성을 넓힐 계획 | O22: 3년간 매출이 줄고(CAGR -8.7%) ROE 1.3%로 수익성도 낮음. PER 63.9배로 주가 부담이 큼 | P22: DART 2025 사업보고서·2024 사업보고서·2026 반기보고서 | Q22: 탈락
A24: 선정 결과
A25: Top 1 | B25: LG유플러스 | C25: 시장은 올해 영업이익 11,498억원을 예상하는데 상반기에만 53.6%를 달성했고, 선행 PER 8.7배·PBR 0.69배로 가격 부담이 낮음. 하반기 개선(컨센서스 가정 +60.5%) 확인이 필요하지만, 상반기 이익이 늘어난 통신주 중 PBR이 가장 낮다고 판단하여 선정.
A26: Top 2 | B26: SK텔레콤 | C26: 시장은 하반기 영업이익을 상반기보다 22.4% 낮게 보지만, 상반기 수준만 유지돼도 연간 22,072억원으로 컨센서스보다 12.6% 많음. PER 46.3배는 해킹사고 연도 기준일 뿐, 선행 PER은 14.1배이고 이익도 회복 중이라고 판단하여 선정.
A27: Top 3 | B27: 에스엠 | C27: 시장은 하반기 영업이익을 작년보다 6.2% 낮게 보지만, 실제 상반기 영업이익은 +14.0%로 성장 중. 하반기가 작년 수준만 돼도 컨센서스보다 3.4% 많고, 선행 PER 15.3배로 가격 부담도 크지 않다고 판단하여 선정.
A28: 탈락 1 | B28: 하이브 | C28: 2025년 영업이익률 1.9%, ROE -7.3%로 이익을 거의 못 냈고 올해 상반기도 영업손실 257억원. 시장 예상을 채우려면 하반기에만 3,106억원을 벌어야 해 달성이 쉽지 않고, 선행 PER 37.7배로 부담도 크다고 판단하여 탈락.
A29: 탈락 2 | B29: CJ ENM | C29: PBR 0.29배로 주가는 낮지만 영업이익률 2.6%·ROE 1.1%로 버는 돈이 적고 빚도 많음(부채비율 151.5%). 상반기 달성률 26.4%로, 낮은 PBR은 기회보다 낮은 수익성의 결과라고 판단하여 탈락.
A30: 탈락 3 | B30: 스튜디오드래곤 | C30: 매출이 3년간 줄고(CAGR -8.7%) ROE 1.3%로 수익성도 낮음. PER 63.9배로 부담이 커, 실적 회복이 연간 숫자로 확인될 때까지 지켜보는 것이 낫다고 판단하여 탈락.
A31: 탈락 4 | B31: 제일기획 | C31: ROE 13.7%로 수익성은 괜찮지만 성장이 느리고(CAGR 2.2%) 올해 상반기 영업이익도 14.2% 감소. 상반기 달성률 39.6%에 국내 광고비도 줄어 업황 회복을 확인하기 어렵다고 판단하여 탈락.
A32: 탈락 5 | B32: 와이지엔터테인먼트 | C32: PER 22.6배로 주가 부담이 크고 ROE 7.4%로 수익성은 낮은 편. 영업이익이 869억원 → -206억원 → 713억원으로 크게 흔들려, 안정성을 중시하는 디펜시브 팀 기준에 맞지 않는다고 판단하여 탈락.

Sheet 소비재·유통
A1: 소비재·유통
A2: ICOK Fund 26-2 · 담당 산업 스크리닝
A4: 팀 | B4: 팀 3 · 내수·디펜시브 | D4: 담당자 | E4: 서민지 | G4: 제출일 | H4: 46287
A5: 지수 비중 | B5: 2.62% | D5: 배정액 | E5: 733,378원 | G5: 종목 수 | H5: 32 | J5: 기준일 | K5: 2026-09-15
A7: 음영 셀은 기입 완료. 흰색 셀만 작성한다.
A9: 하위 테마 | B9: 기업명 | C9: 코드 | D9: 주가 | E9: 시가총액(조) | F9: 지수 비중 | G9: 1주 / 팀예산 | H9: 매수 판정 | I9: 매출 CAGR(3Y) | J9: 영업이익률 | K9: ROE | L9: PER / PBR | M9: 주요 제품 | N9: 시장 포지셔닝 | O9: 투자포인트 / 탈락 사유 | P9: 출처 · 기준일 | Q9: 판정
B10: KT&G | C10: 033780 | D10: 170800 | E10: 17.730826 | F10: 0.0033290475 | G10: 0.038836872 | H10: 가능 | I10: 0.0399 | J10: 0.2194 | K10: 11.77 | L10: 9.984 | M10: 궐련(NGP 포함), 인삼(홍삼), 건강기능식품, 화장품 | N10: 국내 궐련·홍삼 시장 1위, 해외궐련 수출 비중 확대 중인 국내 유일 담배 제조사 | O10: 영업이익률 21.9%·ROE 11.8%로 담배·인삼 고마진 사업 안정적이며 PER 9.98x로 valuation 부담 낮음. 배당수익률 높고 해외궐련 수출 확대가 추가 성장 동력. | P10: 와이즈리포트 | Q10: 보류
B11: LG | C11: 003550 | D11: 114300 | E11: 17.281246 | F11: 0.0032446367 | G11: 0.02598978 | H11: 가능 | I11: 0.0031 | J11: 0.1258 | K11: 2.64 | L11: 40.08 | M11: LG전자·LG화학·LG유플러스·LG생활건강 등 자회사 지분 관리, 브랜드 로열티 수취 | N11: LG그룹 지주회사, 전자·화학·통신 등 계열사를 지배 | O11: 매출 CAGR 0.31%·ROE 2.64%로 사실상 성장 정체. PER 40.08x는 순이익 대비 과도하며 지주사 할인 감안해도 밸류에이션 매력 낮음. | P11: 와이즈리포트 | Q11: 탈락
B12: 에이피알 | C12: 278470 | D12: 361500 | E12: 13.533893 | F12: 0.0025410532 | G12: 0.082198649 | H12: 가능 | I12: 0.566 | J12: 0.2393 | K12: 75.3 | L12: 1.54 | M12: 뷰티디바이스(메디큐브 에이지알), 화장품(메디큐브), 패션(널디) | N12: 홈 뷰티디바이스 국내외 시장 선도, 화장품·디바이스 통합 브랜드 전략 | O12: 매출 CAGR 56.6%·ROE 75.3%로 성장성·자본효율 모두 최상위. 밸류에이션 지표도 낮아(1.54x) 팀 예산 내 최우선 후보로 검토. | P12: 와이즈리포트 | Q12: Top1
B13: 삼양식품 | C13: 003230 | D13: 1277000 | E13: 9.61966 | F13: 0.0018061372 | G13: 0.29036701 | H13: 가능 | I13: 0.372 | J13: 0.2229 | K13: 37.59 | L13: 3.22 | M13: 불닭볶음면 등 라면, 스낵 | N13: 매운맛 라면으로 해외 수출 비중이 절반 이상인 라면 수출 상위 업체 | O13: 매출 CAGR 37.2%·영업이익률 22.3%·ROE 37.6%의 고성장·고수익 조합. 밸류에이션(3.22x)도 부담 없어 해외 수출 모멘텀 지속 시 매력적. | P13: 와이즈리포트 | Q13: Top2
B14: 아모레퍼시픽 | C14: 090430 | D14: 144000 | E14: 8.422957 | F14: 0.0015814505 | G14: 0.03274303 | H14: 가능 | I14: 0.0094 | J14: 0.079 | K14: 4.41 | L14: 23.08 | M14: 설화수·라네즈·이니스프리 등 화장품 브랜드 | N14: 국내 화장품 시장 상위권, 중화권 의존도를 낮추고 미주·유럽 채널 확대 중 | O14: 매출 CAGR 0.94%·영업이익률 7.9%·ROE 4.41%로 수익성 회복이 아직 수치로 확인되지 않음. PER 23.08x는 현재 실적 대비 높아 중국 수요 회복 가시화 전까지 보수적 접근 필요. | P14: 와이즈리포트 | Q14: 보류
B15: 코웨이 | C15: 021240 | D15: 101500 | E15: 7.182894 | F15: 0.0013486227 | G15: 0.023079289 | H15: 가능 | I15: 0.0878 | J15: 0.177 | K15: 18.14 | L15: 5.96 | M15: 정수기·공기청정기·매트리스 등 렌탈 제품 및 코디 방문관리 서비스 | N15: 국내 생활가전 렌탈시장 1위, 말레이시아 등 해외 렌탈사업 확대 중 | O15: 매출 CAGR 8.78%·영업이익률 17.7%·ROE 18.1%로 안정적 수익성 유지. PER 5.96x로 저평가 구간, 렌탈 구독모델 기반 해외(말레이시아 등) 확장이 추가 상승 요인. | P15: 와이즈리포트 | Q15: 보류
B16: 오리온 | C16: 271560 | D16: 116000 | E16: 4.585339 | F16: 0.00086091935 | G16: 0.02637633 | H16: 가능 | I16: 0.0507 | J16: 0.1675 | K16: 10.51 | L16: 9.99 | M16: 초코파이·오감자 등 제과, 스낵 | N16: 국내 제과시장 상위권, 중국·베트남·러시아 해외법인 매출 비중이 높음 | O16: 영업이익률 16.75%·ROE 10.5%로 견조하나 매출 CAGR은 5.07%로 성장 둔화. PER 9.99x는 부담 없는 수준으로 해외법인 실적에 따라 재평가 여지. | P16: 와이즈리포트 | Q16: 보류
B17: LG생활건강 | C17: 051900 | D17: 302000 | E17: 4.522608 | F17: 0.00084914131 | G17: 0.068669411 | H17: 가능 | I17: -0.0401 | J17: 0.0269 | K17: -1.82 | L17: -57.13 | M17: 후·오휘 등 화장품, 샴푸·치약 등 생활용품, 코카콜라 등 음료 | N17: 화장품·생활용품·음료 3개 사업부 보유, 중국향 화장품 수요 회복이 관건 | O17: 매출 CAGR -4.01%로 역성장 중이며 ROE -1.82%(순손실), PER -57.13x로 밸류에이션 산출 자체가 무의미. 중국 화장품 수요 부진 지속으로 탈락. | P17: 와이즈리포트 | Q17: 탈락
B18: CJ | C18: 001040 | D18: 131500 | E18: 3.836775 | F18: 0.00072037288 | G18: 0.029900753 | H18: 가능 | I18: 0.0323 | J18: 0.0562 | K18: 2.69 | L18: 38.57 | M18: CJ제일제당·CJ ENM·CJ대한통운 등 자회사 지분 관리 | N18: 식품·물류·엔터테인먼트 계열사를 지배하는 CJ그룹 지주회사 | O18: ROE 2.69%로 자본효율이 낮고 PER 38.57x는 이익 대비 과대평가. 지주사 할인 감안해도 수익성·밸류에이션 매력이 부족해 탈락 검토. | P18: 와이즈리포트 | Q18: 탈락
B19: 신세계 | C19: 004170 | D19: 368000 | E19: 3.475827 | F19: 0.00065260316 | G19: 0.083676633 | H19: 가능 | I19: -0.0393 | J19: 0.0693 | K19: 0.32 | L19: 354.58 | M19: 백화점(신세계백화점), 면세점 | N19: 백화점 업태 내 프리미엄 포지셔닝, 강남점 등 대형 점포 중심 성장 | O19: 매출 CAGR -3.93%·ROE 0.32%로 사실상 이익창출력 소멸, PER 354.58x는 극단적 고평가. 오프라인 백화점 업황 구조적 정체로 탈락. | P19: 와이즈리포트 | Q19: 탈락
B20: 한국콜마 | C20: 161890 | D20: 144500 | E20: 3.410934 | F20: 0.00064041919 | G20: 0.032856721 | H20: 가능 | I20: 0.1342 | J20: 0.088 | K20: 14.69 | L20: 7.28 | M20: 화장품 ODM/OEM | N20: 국내 화장품 ODM 상위권 업체, 다수 브랜드사에 위탁생산 공급 | O20: 매출 CAGR 13.4%·ROE 14.7%로 양호한 성장·수익성, PER 7.28x로 밸류에이션 매력 있음. K-뷰티 수출 확대에 따른 ODM 물량 증가가 핵심 동력. | P20: 와이즈리포트 | Q20: 보류
B21: 롯데쇼핑 | C21: 023530 | D21: 115300 | E21: 3.261693 | F21: 0.00061239848 | G21: 0.026217162 | H21: 가능 | I21: -0.0389 | J21: 0.0398 | K21: 0.34 | L21: 300.4 | M21: 백화점, 롯데마트, 롭스, 홈쇼핑, 이커머스 | N21: 백화점·마트·이커머스 등 복합 유통망 보유, 오프라인 매출 정체 방어가 과제 | O21: 매출 CAGR -3.89%·ROE 0.34%로 수익성 극도로 저조, PER 300.4x는 실적 대비 과대평가. 오프라인 유통 채널 매출 정체가 지속되어 탈락. | P21: 와이즈리포트 | Q21: 탈락
... B23: 코스맥스 | C23: 192820 | D23: 273000 | E23: 3.098416 | F23: 0.00058174244 | G23: 0.062075328 | H23: 가능 | I23: 0.1445 | J23: 0.0816 | K23: 23.86 | L23: 4.53 | M23: 화장품 ODM | N23: 국내외 화장품 ODM 상위권, 중국·미국·동남아 해외법인 확대 중 | O23: 매출 CAGR 14.5%·ROE 23.9%로 성장성·자본효율 우수, PER 4.53x로 밸류에이션 매력 큼. 해외법인(미국·중국 등) 확대가 실적 개선 견인. | P23: 와이즈리포트 | Q23: Top3
B24: 실리콘투 | C24: 257720 | D24: 43650 | E24: 2.862403 | F24: 0.00053742987 | G24: 0.009925231 | H24: 가능
B25: CJ제일제당 | C25: 097950 | D25: 178200 | E25: 2.682656 | F25: 0.00050368151 | G25: 0.0405195 | H25: 가능
B26: F&F | C26: 383220 | D26: 67300 | E26: 2.578066 | F26: 0.00048404424 | G26: 0.015302819 | H26: 가능
B27: 롯데지주 | C27: 004990 | D27: 24950 | E27: 2.486611 | F27: 0.00046687312 | G27: 0.0056731848 | H27: 가능
B28: 농심 | C28: 004370 | D28: 408500 | E28: 2.484759 | F28: 0.0004665254 | G28: 0.09288561 | H28: 가능
B29: BGF리테일 | C29: 282330 | D29: 141800 | E29: 2.450858 | F29: 0.00046016033 | G29: 0.032242789 | H29: 가능
B30: 영원무역홀딩스 | C30: 009970 | D30: 168500 | E30: 2.182718 | F30: 0.00040981576 | G30: 0.038313893 | H30: 가능
B31: 현대백화점 | C31: 069960 | D31: 98200 | E31: 2.117674 | F31: 0.00039760343 | G31: 0.022328928 | H31: 가능
B32: 미스토홀딩스 | C32: 081660 | D32: 39100 | E32: 2.075891 | F32: 0.00038975848 | G32: 0.0088906422 | H32: 가능
B33: 이마트 | C33: 139480 | D33: 74200 | E33: 2.04761 | F33: 0.00038444858 | G33: 0.016871756 | H33: 가능
B34: GS리테일 | C34: 007070 | D34: 24450 | E34: 2.044201 | F34: 0.00038380853 | G34: 0.0055594937 | H34: 가능
B35: 달바글로벌 | C35: 483650 | D35: 163100 | E35: 2.042977 | F35: 0.00038357871 | G35: 0.037086029 | H35: 가능
... B41: 롯데칠성 | C41: 005300 | D41: 96300 | E41: 0.893557 | F41: 0.00016776961 | G41: 0.021896901 | H41: 가능
A43: 선정 결과
A44: Top 1 | C44: 에이피알
A45: Top 2 | C45: 삼양식품
A46: Top 3 | C46: 코스맥스
A47: 탈락 1 | C47: LG: ROE 2.64%, PER 40.08x , 매출 CAGR 0.31%로 성장 정체인데 밸류에이션만 높음
A48: 탈락 2 | C48: LG생활건강: 매출 CAGR -4.01%, ROE -1.82% (순손실로 PER 산출 자체가 무의미)
A49: 탈락 3 | C49: CJ: ROE 2.69%, PER 38.57x , 저수익성 대비 과대평가
A50: 탈락 4 | C50: 신세계: ROE 0.32%, PER 354.58x , 이익창출력 소멸 수준
...
